<?xml version="1.0" ?>
<!-- Generated using onshape-to-robot -->
<!-- Onshape https://cad.onshape.com/documents/d7eef6374aced10980d655e0/w/a95c1ea2fcec3b2e30db9b5b/e/12a2a0fd368dedeacabed258 -->
<mujoco model="D:\1_repos\dev\mujoco-rl\robot">
  <compiler angle="radian" meshdir="assets" autolimits="true"/>
  <default>
    <default class="D:\1_repos\dev\mujoco-rl\robot">
      <joint frictionloss="0.1" armature="0.005"/>
      <position kp="50" dampratio="1"/>
      <default class="visual">
        <geom type="mesh" contype="0" conaffinity="0" group="2"/>
      </default>
      <default class="collision">
        <geom group="3"/>
      </default>
    </default>
  </default>
  <worldbody>
    <!-- Link body -->
    <body name="body" pos="0 0 0" quat="1 0 0 0" childclass="D:\1_repos\dev\mujoco-rl\robot">
      <freejoint name="body_freejoint"/>
      <inertial pos="-0.00504188 -0.00129679 0.232383" mass="0.128457" fullinertia="3.43693e-05 0.000188026 0.000180806 0 0 8.1445e-08"/>
      <!-- Part mg996r -->
      <geom type="mesh" class="visual" pos="0.0324581 0.0189826 0.252698" quat="0.5 0.5 0.5 -0.5" mesh="mg996r" material="mg996r_material"/>
      <geom type="mesh" class="collision" pos="0.0324581 0.0189826 0.252698" quat="0.5 0.5 0.5 -0.5" mesh="mg996r" material="mg996r_material"/>
      <!-- Part body -->
      <geom type="mesh" class="visual" pos="-0.00504188 -0.00501144 0.204849" quat="1 0 0 0" mesh="body" material="body_material"/>
      <geom type="mesh" class="collision" pos="-0.00504188 -0.00501144 0.204849" quat="1 0 0 0" mesh="body" material="body_material"/>
      <!-- Part mg996r_2 -->
      <geom type="mesh" class="visual" pos="-0.0425419 0.0189826 0.252698" quat="0.5 0.5 0.5 -0.5" mesh="mg996r" material="mg996r_material"/>
      <geom type="mesh" class="collision" pos="-0.0425419 0.0189826 0.252698" quat="0.5 0.5 0.5 -0.5" mesh="mg996r" material="mg996r_material"/>
      <!-- Link leg_hip_l -->
      <body name="leg_hip_l" pos="0.0324581 -0.0210114 0.242349" quat="0.5 -0.5 0.5 0.5">
        <!-- Joint from body to leg_hip_l -->
        <joint axis="0 0 1" name="hip1-l" type="hinge" range="-1.4835298641951802 1.658062789394613"/>
        <inertial pos="0.0162771 -0.00702824 -0.0185862" mass="0.0633239" fullinertia="9.64833e-06 1.45906e-05 1.84718e-05 5.25044e-07 3.99024e-07 -5.5639e-08"/>
        <!-- Part mg996r_3 -->
        <geom type="mesh" class="visual" pos="0.0389247 0.010642 -0.01975" quat="0.0308436 -0.0308436 -0.706434 0.706434" mesh="mg996r" material="mg996r_material"/>
        <geom type="mesh" class="collision" pos="0.0389247 0.010642 -0.01975" quat="0.0308436 -0.0308436 -0.706434 0.706434" mesh="mg996r" material="mg996r_material"/>
        <!-- Part mg996r_straight -->
        <geom type="mesh" class="visual" pos="0 0 -0.00575" quat="0.521334 0.521334 0.477714 0.477714" mesh="mg996r_straight" material="mg996r_straight_material"/>
        <geom type="mesh" class="collision" pos="0 0 -0.00575" quat="0.521334 0.521334 0.477714 0.477714" mesh="mg996r_straight" material="mg996r_straight_material"/>
        <!-- Part leg_hip_l -->
        <geom type="mesh" class="visual" pos="0 -0 -0.00575" quat="0.477714 0.477714 -0.521334 -0.521334" mesh="leg_hip_l" material="leg_hip_l_material"/>
        <geom type="mesh" class="collision" pos="0 -0 -0.00575" quat="0.477714 0.477714 -0.521334 -0.521334" mesh="leg_hip_l" material="leg_hip_l_material"/>
        <!-- Link leg_upper_l -->
        <body name="leg_upper_l" pos="0.0251293 -0.0282978 -0.01975" quat="0.0308436 0.0308436 0.706434 0.706434">
          <!-- Joint from leg_hip_l to leg_upper_l -->
          <joint axis="0 0 1" name="hip2-l" type="hinge" range="-0.698131700797731 2.443460952792062"/>
          <inertial pos="-0.0492957 0.0581811 -0.00253348" mass="0.0743473" fullinertia="5.25789e-05 4.0649e-05 7.93556e-05 3.61047e-05 2.60657e-06 -3.32654e-06"/>
          <!-- Part mg996r_4 -->
          <geom type="mesh" class="visual" pos="-0.0715738 0.0852984 0.018244" quat="0 0.906308 -0.422618 -0" mesh="mg996r" material="mg996r_material"/>
          <geom type="mesh" class="collision" pos="-0.0715738 0.0852984 0.018244" quat="0 0.906308 -0.422618 -0" mesh="mg996r" material="mg996r_material"/>
          <!-- Part mg996r_straight_2 -->
          <geom type="mesh" class="visual" pos="0 -0 -0.00575" quat="0.664463 0.664463 0.241845 0.241845" mesh="mg996r_straight" material="mg996r_straight_material"/>
          <geom type="mesh" class="collision" pos="0 -0 -0.00575" quat="0.664463 0.664463 0.241845 0.241845" mesh="mg996r_straight" material="mg996r_straight_material"/>
          <!-- Part leg_upper_l -->
          <geom type="mesh" class="visual" pos="-0 -0 -0.00575" quat="0.640856 0.298836 0.640856 -0.298836" mesh="leg_upper_l" material="leg_upper_l_material"/>
          <geom type="mesh" class="collision" pos="-0 -0 -0.00575" quat="0.640856 0.298836 0.640856 -0.298836" mesh="leg_upper_l" material="leg_upper_l_material"/>
          <!-- Link leg_lower_l -->
          <body name="leg_lower_l" pos="-0.0649215 0.0773705 -0.02175" quat="0.906308 -0 0 -0.422618">
            <!-- Joint from leg_upper_l to leg_lower_l -->
            <joint axis="0 0 1" name="knee-l" type="hinge" range="-1.6580627893946145 1.4835298641951786"/>
            <inertial pos="0.00837528 -0.0957299 -0.00588184" mass="0.109055" fullinertia="0.000331126 1.27446e-05 0.000336642 2.80696e-05 -3.39852e-07 3.88454e-06"/>
            <!-- Part leg_lower_l -->
            <geom type="mesh" class="visual" pos="0 -0 -0.00575" quat="0.477714 -0.521334 0.477714 0.521334" mesh="leg_lower_l" material="leg_lower_l_material"/>
            <geom type="mesh" class="collision" pos="0 -0 -0.00575" quat="0.477714 -0.521334 0.477714 0.521334" mesh="leg_lower_l" material="leg_lower_l_material"/>
            <!-- Part mg996r_straight_3 -->
            <geom type="mesh" class="visual" pos="-0 0 -0.00575" quat="0.0308436 0.0308436 -0.706434 -0.706434" mesh="mg996r_straight" material="mg996r_straight_material"/>
            <geom type="mesh" class="collision" pos="-0 0 -0.00575" quat="0.0308436 0.0308436 -0.706434 -0.706434" mesh="mg996r_straight" material="mg996r_straight_material"/>
          </body>
        </body>
      </body>
      <!-- Link leg_hip_r -->
      <body name="leg_hip_r" pos="-0.0425419 -0.0210114 0.242349" quat="0.5 -0.5 0.5 0.5">
        <!-- Joint from body to leg_hip_r -->
        <joint axis="0 0 1" name="hip1-r" type="hinge" range="-1.6580627893946132 1.48352986419518"/>
        <inertial pos="0.0162771 0.00702824 -0.0185862" mass="0.0633239" fullinertia="9.64833e-06 1.45906e-05 1.84718e-05 -5.25044e-07 3.99025e-07 5.5639e-08"/>
        <!-- Part leg_hip_r -->
        <geom type="mesh" class="visual" pos="0.00139449 -0.0159391 -0.00575" quat="0.521334 0.521334 -0.477714 -0.477714" mesh="leg_hip_r" material="leg_hip_r_material"/>
        <geom type="mesh" class="collision" pos="0.00139449 -0.0159391 -0.00575" quat="0.521334 0.521334 -0.477714 -0.477714" mesh="leg_hip_r" material="leg_hip_r_material"/>
        <!-- Part mg996r_5 -->
        <geom type="mesh" class="visual" pos="0.0389247 -0.010642 -0.01975" quat="0.0308436 0.0308436 -0.706434 -0.706434" mesh="mg996r" material="mg996r_material"/>
        <geom type="mesh" class="collision" pos="0.0389247 -0.010642 -0.01975" quat="0.0308436 0.0308436 -0.706434 -0.706434" mesh="mg996r" material="mg996r_material"/>
        <!-- Part mg996r_straight_4 -->
        <geom type="mesh" class="visual" pos="0 0 -0.00575" quat="0.521334 0.521334 -0.477714 -0.477714" mesh="mg996r_straight" material="mg996r_straight_material"/>
        <geom type="mesh" class="collision" pos="0 0 -0.00575" quat="0.521334 0.521334 -0.477714 -0.477714" mesh="mg996r_straight" material="mg996r_straight_material"/>
        <!-- Link leg_upper_r -->
        <body name="leg_upper_r" pos="0.0251293 0.0282978 -0.01975" quat="0.0308436 -0.0308436 0.706434 -0.706434">
          <!-- Joint from leg_hip_r to leg_upper_r -->
          <joint axis="0 0 1" name="hip2-r" type="hinge" range="-2.4434609527920617 0.6981317007977315"/>
          <inertial pos="-0.0492957 -0.0581811 -0.00253348" mass="0.0743473" fullinertia="5.25789e-05 4.0649e-05 7.93556e-05 -3.61047e-05 2.60657e-06 3.32654e-06"/>
          <!-- Part mg996r_straight_5 -->
          <geom type="mesh" class="visual" pos="0 0 -0.00575" quat="0.241845 0.241845 0.664463 0.664463" mesh="mg996r_straight" material="mg996r_straight_material"/>
          <geom type="mesh" class="collision" pos="0 0 -0.00575" quat="0.241845 0.241845 0.664463 0.664463" mesh="mg996r_straight" material="mg996r_straight_material"/>
          <!-- Part mg996r_6 -->
          <geom type="mesh" class="visual" pos="-0.0715738 -0.0852984 0.018244" quat="0 -0.906308 -0.422618 -0" mesh="mg996r" material="mg996r_material"/>
          <geom type="mesh" class="collision" pos="-0.0715738 -0.0852984 0.018244" quat="0 -0.906308 -0.422618 -0" mesh="mg996r" material="mg996r_material"/>
          <!-- Part leg_upper_r -->
          <geom type="mesh" class="visual" pos="0 0 -0.00105" quat="0.298836 -0.640856 -0.298836 -0.640856" mesh="leg_upper_r" material="leg_upper_r_material"/>
          <geom type="mesh" class="collision" pos="0 0 -0.00105" quat="0.298836 -0.640856 -0.298836 -0.640856" mesh="leg_upper_r" material="leg_upper_r_material"/>
          <!-- Link leg_lower_r -->
          <body name="leg_lower_r" pos="-0.0649215 -0.0773705 -0.02175" quat="0.906308 0 -0 0.422618">
            <!-- Joint from leg_upper_r to leg_lower_r -->
            <joint axis="0 0 1" name="knee-r" type="hinge" range="-1.4816235885685867 1.6599690650212064"/>
            <inertial pos="0.00855778 0.0957138 -0.00588181" mass="0.109055" fullinertia="0.000331018 1.28527e-05 0.000336642 -2.86763e-05 -3.47275e-07 -3.88388e-06"/>
            <!-- Part leg_lower_r -->
            <geom type="mesh" class="visual" pos="0 0 0.06095" quat="0.521789 0.477217 -0.521789 0.477217" mesh="leg_lower_r" material="leg_lower_r_material"/>
            <geom type="mesh" class="collision" pos="0 0 0.06095" quat="0.521789 0.477217 -0.521789 0.477217" mesh="leg_lower_r" material="leg_lower_r_material"/>
            <!-- Part mg996r_straight_6 -->
            <geom type="mesh" class="visual" pos="0 -0 -0.00575" quat="0.706404 0.706404 -0.0315169 -0.0315169" mesh="mg996r_straight" material="mg996r_straight_material"/>
            <geom type="mesh" class="collision" pos="0 -0 -0.00575" quat="0.706404 0.706404 -0.0315169 -0.0315169" mesh="mg996r_straight" material="mg996r_straight_material"/>
          </body>
        </body>
      </body>
    </body>
  </worldbody>
  <asset>
    <mesh file="leg_hip_r.stl"/>
    <mesh file="leg_upper_r.stl"/>
    <mesh file="mg996r.stl"/>
    <mesh file="body.stl"/>
    <mesh file="leg_lower_r.stl"/>
    <mesh file="leg_hip_l.stl"/>
    <mesh file="leg_lower_l.stl"/>
    <mesh file="mg996r_straight.stl"/>
    <mesh file="leg_upper_l.stl"/>
    <material name="mg996r_material" rgba="0.301961 0.301961 0.301961 1"/>
    <material name="body_material" rgba="0.615686 0.811765 0.929412 1"/>
    <material name="mg996r_straight_material" rgba="0.439216 0.47451 0.501961 1"/>
    <material name="leg_hip_l_material" rgba="0.615686 0.811765 0.929412 1"/>
    <material name="leg_upper_l_material" rgba="0.615686 0.811765 0.929412 1"/>
    <material name="leg_lower_l_material" rgba="0.615686 0.811765 0.929412 1"/>
    <material name="leg_hip_r_material" rgba="0.615686 0.811765 0.929412 1"/>
    <material name="leg_upper_r_material" rgba="0.615686 0.811765 0.929412 1"/>
    <material name="leg_lower_r_material" rgba="0.615686 0.811765 0.929412 1"/>
  </asset>
  <actuator>
    <position class="D:\1_repos\dev\mujoco-rl\robot" name="hip1-l" joint="hip1-l" inheritrange="1"/>
    <position class="D:\1_repos\dev\mujoco-rl\robot" name="hip2-l" joint="hip2-l" inheritrange="1"/>
    <position class="D:\1_repos\dev\mujoco-rl\robot" name="knee-l" joint="knee-l" inheritrange="1"/>
    <position class="D:\1_repos\dev\mujoco-rl\robot" name="hip1-r" joint="hip1-r" inheritrange="1"/>
    <position class="D:\1_repos\dev\mujoco-rl\robot" name="hip2-r" joint="hip2-r" inheritrange="1"/>
    <position class="D:\1_repos\dev\mujoco-rl\robot" name="knee-r" joint="knee-r" inheritrange="1"/>
  </actuator>
  <equality/>
</mujoco>
