<?xml version="1.0" ?>
<!-- Generated using onshape-to-robot -->
<!-- Onshape https://cad.onshape.com/documents/d7eef6374aced10980d655e0/w/a95c1ea2fcec3b2e30db9b5b/e/e929eb8ea27c778bb70e0c8e -->
<mujoco model="arm-v2">
  <compiler angle="radian" meshdir="assets" autolimits="true"/>
  <default>
    <default class="arm-v2">
      <joint frictionloss="0.1" armature="0.005"/>
      <position kp="50" dampratio="1"/>
      <default class="visual">
        <geom type="mesh" contype="0" conaffinity="0" group="2"/>
      </default>
      <default class="collision">
        <geom group="3"/>
      </default>
    </default>
  </default>
  <worldbody>
    <!-- Link base -->
    <body name="base" pos="0 0 0" quat="1 0 0 0" childclass="arm-v2">
      <inertial pos="0 0.00388636 0.0129496" mass="0.331827" fullinertia="0.000318825 0.000259631 0.000528752 0 0 -8.40424e-06"/>
      <!-- Part base -->
      <geom type="mesh" class="visual" pos="0 0 0" quat="1 0 0 0" mesh="base" material="base_material"/>
      <geom type="mesh" class="collision" pos="0 0 0" quat="1 0 0 0" mesh="base" material="base_material"/>
      <!-- Link seg1 -->
      <body name="seg1" pos="0 0 0.028" quat="-0 -1 0 0">
        <!-- Joint from base to seg1 -->
        <joint axis="0 0 1" name="base" type="hinge" range="-1.5707963267948966 1.5707963267948966"/>
        <inertial pos="-0 0.00623987 -0.0202701" mass="0.0748252" fullinertia="6.19727e-05 5.24779e-05 5.79472e-05 -0 0 1.17384e-05"/>
        <!-- Part seg1 -->
        <geom type="mesh" class="visual" pos="-0 0 -0.002" quat="0 1 0 0" mesh="seg1" material="seg1_material"/>
        <geom type="mesh" class="collision" pos="-0 0 -0.002" quat="0 1 0 0" mesh="seg1" material="seg1_material"/>
        <!-- Link seg2 -->
        <body name="seg2" pos="0.02 0.048 -0.05" quat="0.5 0.5 -0.5 -0.5">
          <!-- Joint from seg1 to seg2 -->
          <joint axis="0 0 1" name="shoulder" type="hinge" range="-2.687807048071267 0.5235987755982996"/>
          <inertial pos="0.0259241 -0.0137918 0.02" mass="0.108178" fullinertia="6.43247e-05 0.000161173 0.000192018 6.76584e-05 -6e-12 3e-12"/>
          <!-- Part seg2 -->
          <geom type="mesh" class="visual" pos="0 -0 0.02" quat="0.683013 0.183013 0.683013 -0.183013" mesh="seg2" material="seg2_material"/>
          <geom type="mesh" class="collision" pos="0 -0 0.02" quat="0.683013 0.183013 0.683013 -0.183013" mesh="seg2" material="seg2_material"/>
        </body>
      </body>
    </body>
  </worldbody>
  <asset>
    <mesh file="base.stl"/>
    <mesh file="seg2.stl"/>
    <mesh file="seg1.stl"/>
    <material name="base_material" rgba="0.615686 0.811765 0.929412 1"/>
    <material name="seg1_material" rgba="0.615686 0.811765 0.929412 1"/>
    <material name="seg2_material" rgba="0.615686 0.811765 0.929412 1"/>
  </asset>
  <actuator>
    <position class="arm-v2" name="base" joint="base" inheritrange="1"/>
    <position class="arm-v2" name="shoulder" joint="shoulder" inheritrange="1"/>
  </actuator>
  <equality/>
</mujoco>
